<?xml version="1.0" ?>
<!-- =================================================================================== -->
<!-- |    This document was autogenerated by xacro from urdf/iiwa14_polytope_collision.urdf.xacro | -->
<!-- |    EDITING THIS FILE BY HAND IS NOT RECOMMENDED                                 | -->
<!-- =================================================================================== -->
<!-- ===================================================================== -->
<!-- Collision models: complex meshes can drastically affect run time.
     Therefore most collision models are omitted in this model and link 7 uses a
     polytope model.
-->
<!-- ===================================================================== -->
<robot name="iiwa14"
  xmlns:xacro="http://www.ros.org/wiki/xacro">
  <!-- Import Rviz colors -->
  <material name="Black">
    <color rgba="0.0 0.0 0.0 1.0"/>
  </material>
  <material name="Blue">
    <color rgba="0.0 0.0 0.8 1.0"/>
  </material>
  <material name="Green">
    <color rgba="0.0 0.8 0.0 1.0"/>
  </material>
  <material name="Grey">
    <color rgba="0.4 0.4 0.4 1.0"/>
  </material>
  <material name="Orange">
    <color rgba="1.0 0.423529411765 0.0392156862745 1.0"/>
  </material>
  <material name="Brown">
    <color rgba="0.870588235294 0.811764705882 0.764705882353 1.0"/>
  </material>
  <material name="Red">
    <color rgba="0.8 0.0 0.0 1.0"/>
  </material>
  <material name="White">
    <color rgba="1.0 1.0 1.0 1.0"/>
  </material>
  <!-- Defines a base link that will serve as the model's root. -->
  <link name="base_link"/>

  <!--joint between {parent} and link_0-->
  <joint name="iiwa_base_joint" type="fixed">
    <origin rpy="0 0 0" xyz="0 0 0"/>
    <parent link="base_link"/>
    <child link="iiwa_link_0"/>
  </joint>
  <link name="iiwa_link_0">
    <inertial>
      <origin rpy="0 0 0" xyz="-0.1 0 0.07"/>
      <mass value="5"/>
      <inertia ixx="0.05" ixy="0" ixz="0" iyy="0.06" iyz="0" izz="0.03"/>
    </inertial>
    <collision>
      <origin rpy="0 0 0" xyz="-0.015 0 0.07"/>
      <geometry>
        <cylinder length="0.17" radius="0.139"/>
      </geometry>
    </collision>
    <visual>
      <origin rpy="0 0 0" xyz="-0.015 0 0.07"/>
      <geometry>
        <cylinder length="0.17" radius="0.139"/>
      </geometry>
    </visual>
    <self_collision_checking>
      <origin rpy="0 0 0" xyz="0 0 0"/>
      <geometry>
        <capsule length="0.25" radius="0.15"/>
      </geometry>
    </self_collision_checking>
  </link>
  <link name="iiwa_link_1">
    <inertial>
      <origin rpy="0 0 0" xyz="0 -0.03 0.12"/>
      <mass value="5.76"/>
      <!--4-->
      <!--<inertia ixx="0.1" ixy="0" ixz="0" iyy="0.09" iyz="0" izz="0.02"/>-->
      <!--<original urdf value>-->
      <inertia ixx="0.033" ixy="0" ixz="0" iyy="0.0333" iyz="0.004887" izz="0.0123"/>
      <!--<TODO(YeZhao): lumped parameter estimation>-->
    </inertial>
    <collision>
      <origin rpy="0 0 0" xyz="0 -0.014 0.14"/>
      <geometry>
        <cylinder length="0.29" radius="0.101"/>
      </geometry>
    </collision>
    <visual>
      <origin rpy="0 0 0" xyz="0 -0.014 0.14"/>
      <geometry>
        <cylinder length="0.29" radius="0.101"/>
      </geometry>
    </visual>
  </link>
  <link name="iiwa_link_2">
    <inertial>
      <origin rpy="0 0 0" xyz="0.0003 0.059 0.042"/>
      <mass value="6.35"/>
      <!-- 3.95 kuka CAD value-->
      <!--4 original urdf value-->
      <!--<inertia ixx="0.05" ixy="0" ixz="0" iyy="0.018" iyz="0" izz="0.044"/>-->
      <!--<original urdf value>-->
      <inertia ixx="0.0305" ixy="0" ixz="0" iyy="0.0304" iyz="0.004887" izz="0.011"/>
    </inertial>
    <collision>
      <origin rpy="1.57079632679 0 0" xyz="0 0.0725 0.035"/>
      <geometry>
        <cylinder length="0.323" radius="0.101"/>
      </geometry>
    </collision>
    <visual>
      <origin rpy="1.57079632679 0 0" xyz="0 0.0725 0.035"/>
      <geometry>
        <cylinder length="0.323" radius="0.101"/>
      </geometry>
    </visual>
  </link>
  <link name="iiwa_link_3">
    <inertial>
      <origin rpy="0 0 0" xyz="0 0.03 0.13"/>
      <mass value="3.5"/>
      <!--3.18 kuka CAD value-->
      <!--4 original urdf value-->
      <!--<inertia ixx="0.08" ixy="0" ixz="0" iyy="0.075" iyz="0" izz="0.01"/>-->
      <!--<original urdf value>-->
      <inertia ixx="0.025" ixy="0" ixz="0" iyy="0.0238" iyz="0.00487" izz="0.0076"/>
    </inertial>
    <collision>
      <origin rpy="0 0 0" xyz="0 0.025 0.1205"/>
      <geometry>
        <cylinder length="0.257" radius="0.092"/>
      </geometry>
    </collision>
    <visual>
      <origin rpy="0 0 0" xyz="0 0.025 0.1205"/>
      <geometry>
        <cylinder length="0.257" radius="0.092"/>
      </geometry>
    </visual>
  </link>
  <link name="iiwa_link_4">
    <inertial>
      <origin rpy="0 0 0" xyz="0 0.067 0.034"/>
      <mass value="3.5"/>
      <!--2.74 kuka CAD value-->
      <!--4 original urdf value-->
      <!--<inertia ixx="0.03" ixy="0" ixz="0" iyy="0.01" iyz="0" izz="0.029"/>-->
      <!--<original urdf value>-->
      <inertia ixx="0.017" ixy="0" ixz="0" iyy="0.0164" iyz="0.00284" izz="0.006"/>
    </inertial>
    <collision>
      <origin rpy="1.57079632679 0 0" xyz="0 0.0725 0.025"/>
      <geometry>
        <cylinder length="0.283" radius="0.092"/>
      </geometry>
    </collision>
    <visual>
      <origin rpy="1.57079632679 0 0" xyz="0 0.0725 0.025"/>
      <geometry>
        <cylinder length="0.283" radius="0.092"/>
      </geometry>
    </visual>
  </link>
  <link name="iiwa_link_5">
    <inertial>
      <origin rpy="0 0 0" xyz="0.0001 0.021 0.076"/>
      <mass value="3.5"/>
      <!--1.69 kuka CAD value-->
      <!--1.7 original urdf value-->
      <!--<inertia ixx="0.02" ixy="0" ixz="0" iyy="0.018" iyz="0" izz="0.005"/>-->
      <!--<original urdf value>-->
      <inertia ixx="0.01" ixy="0" ixz="0" iyy="0.0087" iyz="0.00309" izz="0.00449"/>
    </inertial>
    <!-- <collision>
      <origin rpy="-0.3 0 0" xyz="0 0.03 0.13"/>
      <geometry>
          <cylinder radius="0.07" length="0.29"/>
      </geometry>
    </collision> -->
    <!-- <visual>
      <origin rpy="-0.3 0 0" xyz="0 0.03 0.13"/>
      <geometry>
          <cylinder radius="0.07" length="0.29"/>
      </geometry>
    </visual> -->
    <collision>
      <origin rpy="0 0 0" xyz="0 0 0.06"/>
      <geometry>
        <cylinder length="0.12" radius="0.07"/>
      </geometry>
    </collision>
    <visual>
      <origin rpy="0 0 0" xyz="0 0 0.06"/>
      <geometry>
        <cylinder length="0.12" radius="0.07"/>
      </geometry>
    </visual>
    <collision>
      <origin rpy="0 0 0" xyz="0 0.0757 0.1175"/>
      <geometry>
        <box size="0.105 0.05 0.235"/>
      </geometry>
    </collision>
    <visual>
      <origin rpy="0 0 0" xyz="0 0.0757 0.1175"/>
      <geometry>
        <box size="0.105 0.05 0.235"/>
      </geometry>
    </visual>
  </link>
  <link name="iiwa_link_6">
    <inertial>
      <origin rpy="0 0 0" xyz="0 0.0006 0.0004"/>
      <mass value="1.8"/>
      <!--1.8 kuka CAD value-->
      <!--1.8 original urdf value-->
      <!--<inertia ixx="0.005" ixy="0" ixz="0" iyy="0.0036" iyz="0" izz="0.0047"/>-->
      <!--<original urdf value>-->
      <inertia ixx="0.0049" ixy="0" ixz="0" iyy="0.0047" iyz="0.000246" izz="0.0036"/>
    </inertial>
    <collision>
      <origin rpy="1.57079632679 0 0" xyz="0 0 0 "/>
      <geometry>
        <cylinder length="0.165" radius="0.07"/>
      </geometry>
    </collision>
    <visual>
      <origin rpy="1.57079632679 0 0" xyz="0 0 0 "/>
      <geometry>
        <cylinder length="0.165" radius="0.07"/>
      </geometry>
    </visual>
  </link>
  <!-- ***** Old iiwa link given by Harvard ***** -->
  <!-- <link name="iiwa_link_7">
    <inertial>
      <origin rpy="0 0 0" xyz="0 0 0.02"/>
      <mass value="1.2"/>
      <inertia ixx="0.0002" ixy="0" ixz="0" iyy="0.0002" iyz="0" izz="0.0003"/>
    </inertial>
    <collision>
      <origin rpy="0 0 0" xyz="0 0 0"/>
      <geometry>
        <mesh filename="meshes/collision/link_7.obj"/>
      </geometry>
    </collision>
    <visual>
      <origin rpy="0 0 0" xyz="0 0 0"/>
      <geometry>
        <mesh filename="meshes/collision/link_7.obj"/>
      </geometry>
    </visual>
  </link> -->
  <link name="iiwa_link_7">
    <inertial>
      <origin rpy="0 0 0" xyz="-0.000422054623772967 0.000362352529004074 0.0273579564924244"/>
      <mass value="0.423885822582419"/>
      <inertia ixx="0.000380607898359458" ixy="8.95782182648185E-07" ixz="4.8884089309728E-06" iyy="0.000379401144876245" iyz="-4.74644167053496E-07" izz="0.000482397069304142"/>
    </inertial>
    <!-- <collision>
      <origin rpy="0 0 0" xyz="0 0 0.035"/>
      <geometry>
          <cylinder radius="0.07" length="0.07"/>
      </geometry>
    </collision> -->
    <!-- <visual>
      <origin rpy="0 0 0" xyz="0 0 0.035"/>
      <geometry>
          <cylinder radius="0.07" length="0.07"/>
      </geometry>
    </visual> -->
    <collision>
      <origin rpy="0 0 0" xyz="0.01095 0.01637 0.0355"/>
      <geometry>
        <box size="0.13 0.14 0.071"/>
      </geometry>
    </collision>
    <visual>
      <origin rpy="0 0 0" xyz="0.01095 0.01637 0.0355"/>
      <geometry>
        <box size="0.13 0.14 0.071"/>
      </geometry>
    </visual>
  </link>
  <link name="iiwa_link_ee_kuka"/>
  <link name="iiwa_link_ee"/>
  <!-- <link name="iiwa_tool_frame"/>
  <link name="iiwa_palm_frame"/> -->
  <joint name="iiwa_joint_1" type="revolute">
    <parent link="iiwa_link_0"/>
    <child link="iiwa_link_1"/>
    <origin rpy="0 0 0" xyz="0 0 0.1575"/>
    <axis xyz="0 0 1"/>
    <limit effort="300" lower="-2.96705972839" upper="2.96705972839" velocity="10"/>
    <!-- <safety_controller k_position="100" k_velocity="2" soft_lower_limit="-2.93215314335" soft_upper_limit="2.93215314335"/> -->
    <dynamics damping="0.5"/>
  </joint>
  <joint name="iiwa_joint_2" type="revolute">
    <parent link="iiwa_link_1"/>
    <child link="iiwa_link_2"/>
    <origin rpy="1.57079632679   0 3.14159265359" xyz="0 0 0.2025"/>
    <axis xyz="0 0 1"/>
    <limit effort="300" lower="-2.09439510239" upper="2.09439510239" velocity="10"/>
    <!-- <safety_controller k_position="100" k_velocity="2" soft_lower_limit="-2.05948851735" soft_upper_limit="2.05948851735"/> -->
    <dynamics damping="0.5"/>
  </joint>
  <joint name="iiwa_joint_3" type="revolute">
    <parent link="iiwa_link_2"/>
    <child link="iiwa_link_3"/>
    <origin rpy="1.57079632679 0 3.14159265359" xyz="0 0.2375 0"/>
    <axis xyz="0 0 1"/>
    <limit effort="300" lower="-2.96705972839" upper="2.96705972839" velocity="10"/>
    <!-- <safety_controller k_position="100" k_velocity="2" soft_lower_limit="-2.05948851735" soft_upper_limit="2.05948851735"/> -->
    <dynamics damping="0.5"/>
  </joint>
  <joint name="iiwa_joint_4" type="revolute">
    <parent link="iiwa_link_3"/>
    <child link="iiwa_link_4"/>
    <origin rpy="1.57079632679 0 0" xyz="0 0 0.1825"/>
    <axis xyz="0 0 1"/>
    <limit effort="300" lower="-2.09439510239" upper="2.09439510239" velocity="10"/>
    <!-- <safety_controller k_position="100" k_velocity="2" soft_lower_limit="-2.05948851735" soft_upper_limit="2.05948851735"/> -->
    <dynamics damping="0.5"/>
  </joint>
  <joint name="iiwa_joint_5" type="revolute">
    <parent link="iiwa_link_4"/>
    <child link="iiwa_link_5"/>
    <origin rpy="-1.57079632679 3.14159265359 0" xyz="0 0.2175 0"/>
    <axis xyz="0 0 1"/>
    <limit effort="300" lower="-2.96705972839" upper="2.96705972839" velocity="10"/>
    <!-- <safety_controller k_position="100" k_velocity="2" soft_lower_limit="-2.05948851735" soft_upper_limit="2.05948851735"/> -->
    <dynamics damping="0.5"/>
  </joint>
  <joint name="iiwa_joint_6" type="revolute">
    <parent link="iiwa_link_5"/>
    <child link="iiwa_link_6"/>
    <origin rpy="1.57079632679 0 0" xyz="0 0 0.1825"/>
    <axis xyz="0 0 1"/>
    <limit effort="300" lower="-2.09439510239" upper="2.09439510239" velocity="10"/>
    <!-- <safety_controller k_position="100" k_velocity="2" soft_lower_limit="-2.05948851735" soft_upper_limit="2.05948851735"/> -->
    <dynamics damping="0.5"/>
  </joint>
  <joint name="iiwa_joint_7" type="revolute">
    <parent link="iiwa_link_6"/>
    <child link="iiwa_link_7"/>
    <origin rpy="-1.57079632679 3.14159265359 0" xyz="0 0.081 0"/>
    <axis xyz="0 0 1"/>
    <!-- <limit effort="300" lower="-3.05432619099" upper="3.05432619099" velocity="10"/> -->
    <limit effort="300" lower="-3.05432619099" upper="3.05432619099" velocity="10"/>
    <!-- <safety_controller k_position="100" k_velocity="2" soft_lower_limit="-3.01941960595" soft_upper_limit="3.01941960595"/> -->
    <dynamics damping="0.5"/>
  </joint>
  <joint name="iiwa_joint_ee" type="fixed">
    <parent link="iiwa_link_7"/>
    <child link="iiwa_link_ee_kuka"/>
    <origin rpy="3.14159265359 3.14159265359 3.14159265359" xyz="0 0 0.045"/>
    <axis xyz="0 0 1"/>
  </joint>
  <joint name="tool0_joint" type="fixed">
    <parent link="iiwa_link_7"/>
    <child link="iiwa_link_ee"/>
    <origin rpy="0 -1.57079632679 0" xyz="0 0 0.045"/>
  </joint>
  <!--  <joint name="iiwa_joint_ee_kuka" type="fixed">
    <parent link="iiwa_link_7"/>
    <child link="iiwa_link_ee_kuka"/>
    <origin rpy="3.14159265359 3.14159265359 3.14159265359" xyz="0 0 0.045"/>
    <axis xyz="0 0 1"/>
  </joint>
  <joint name="iiwa_joint_ee" type="fixed">
    <parent link="iiwa_link_7"/>
    <child link="iiwa_link_ee"/>
    <origin rpy="0 -1.57079632679 0" xyz="0 0 0.045"/>
  </joint>-->
  <!-- <joint name="iiwa_tool_joint" type="fixed">
    <parent link="iiwa_link_ee"/>
    <child link="iiwa_tool_frame"/>
    <origin xyz="0.125 0.0 0.0" rpy="0.0 0.0 0.0"/>
  </joint>
  <joint name="iiwa_palm_joint" type="fixed">
    <parent link="iiwa_link_ee"/>
    <child link="iiwa_palm_frame"/>
    <origin xyz="0.1008875 0.0 0.0" rpy="0.0 0.0 0.0"/>
  </joint> -->
  <gazebo reference="iiwa_link_0">
    <mu1>0.2</mu1>
    <mu2>0.2</mu2>
  </gazebo>
  <gazebo reference="iiwa_link_1">
    <mu1>0.2</mu1>
    <mu2>0.2</mu2>
  </gazebo>
  <gazebo reference="iiwa_link_2">
    <mu1>0.2</mu1>
    <mu2>0.2</mu2>
  </gazebo>
  <gazebo reference="iiwa_link_3">
    <mu1>0.2</mu1>
    <mu2>0.2</mu2>
  </gazebo>
  <gazebo reference="iiwa_link_4">
    <mu1>0.2</mu1>
    <mu2>0.2</mu2>
  </gazebo>
  <gazebo reference="iiwa_link_5">
    <mu1>0.2</mu1>
    <mu2>0.2</mu2>
  </gazebo>
  <gazebo reference="iiwa_link_6">
    <mu1>0.2</mu1>
    <mu2>0.2</mu2>
  </gazebo>
  <gazebo reference="iiwa_link_7">
    <mu1>0.2</mu1>
    <mu2>0.2</mu2>
  </gazebo>
  <transmission name="iiwa_tran_1">
    <type>transmission_interface/SimpleTransmission</type>
    <joint name="iiwa_joint_1">
      <hardwareInterface>PositionJointInterface</hardwareInterface>
    </joint>
    <actuator name="iiwa_motor_1">
      <hardwareInterface>PositionJointInterface</hardwareInterface>
      <mechanicalReduction>1</mechanicalReduction>
    </actuator>
  </transmission>
  <transmission name="iiwa_tran_2">
    <type>transmission_interface/SimpleTransmission</type>
    <joint name="iiwa_joint_2">
      <hardwareInterface>PositionJointInterface</hardwareInterface>
    </joint>
    <actuator name="iiwa_motor_2">
      <hardwareInterface>PositionJointInterface</hardwareInterface>
      <mechanicalReduction>1</mechanicalReduction>
    </actuator>
  </transmission>
  <transmission name="iiwa_tran_3">
    <type>transmission_interface/SimpleTransmission</type>
    <joint name="iiwa_joint_3">
      <hardwareInterface>PositionJointInterface</hardwareInterface>
    </joint>
    <actuator name="iiwa_motor_3">
      <hardwareInterface>PositionJointInterface</hardwareInterface>
      <mechanicalReduction>1</mechanicalReduction>
    </actuator>
  </transmission>
  <transmission name="iiwa_tran_4">
    <type>transmission_interface/SimpleTransmission</type>
    <joint name="iiwa_joint_4">
      <hardwareInterface>PositionJointInterface</hardwareInterface>
    </joint>
    <actuator name="iiwa_motor_4">
      <hardwareInterface>PositionJointInterface</hardwareInterface>
      <mechanicalReduction>1</mechanicalReduction>
    </actuator>
  </transmission>
  <transmission name="iiwa_tran_5">
    <type>transmission_interface/SimpleTransmission</type>
    <joint name="iiwa_joint_5">
      <hardwareInterface>PositionJointInterface</hardwareInterface>
    </joint>
    <actuator name="iiwa_motor_5">
      <hardwareInterface>PositionJointInterface</hardwareInterface>
      <mechanicalReduction>1</mechanicalReduction>
    </actuator>
  </transmission>
  <transmission name="iiwa_tran_6">
    <type>transmission_interface/SimpleTransmission</type>
    <joint name="iiwa_joint_6">
      <hardwareInterface>PositionJointInterface</hardwareInterface>
    </joint>
    <actuator name="iiwa_motor_6">
      <hardwareInterface>PositionJointInterface</hardwareInterface>
      <mechanicalReduction>1</mechanicalReduction>
    </actuator>
  </transmission>
  <transmission name="iiwa_tran_7">
    <type>transmission_interface/SimpleTransmission</type>
    <joint name="iiwa_joint_7">
      <hardwareInterface>PositionJointInterface</hardwareInterface>
    </joint>
    <actuator name="iiwa_motor_7">
      <hardwareInterface>PositionJointInterface</hardwareInterface>
      <mechanicalReduction>1</mechanicalReduction>
    </actuator>
  </transmission>
  <drake:collision_filter_group name="iiwa">
    <drake:member link="iiwa_link_0"/>
    <drake:member link="iiwa_link_1"/>
    <drake:member link="iiwa_link_2"/>
    <drake:member link="iiwa_link_3"/>
    <drake:member link="iiwa_link_4"/>
    <drake:member link="iiwa_link_5"/>
    <drake:member link="iiwa_link_6"/>
    <drake:member link="iiwa_link_7"/>
    <drake:ignored_collision_filter_group name="iiwa"/>
  </drake:collision_filter_group>
</robot>
